<?xml version="1.0" ?>
<robot name="yefan" xmlns:xacro="http://www.ros.org/wiki/xacro">
  <joint name="joint1" type="revolute">
    <origin rpy="0 0 0" xyz="0 0 0.346"/>
    <parent link="link1"/>
    <child link="link2"/>
    <axis xyz="0 0 1"/>
    <limit effort="3000" lower="-3.14" upper="3.14" velocity="2.26893"/>
    <!--  bound +-185 limit effort ? and dynamics? -->
    <dynamics damping="125" friction="155"/>
    <!-- Initial deflection if the generalized ik solution for 6 joint robot can be applied -->
    <general6ik>0</general6ik> 
  </joint>
  <joint name="joint2" type="revolute">
    <origin rpy="0 0 0" xyz="0.312 0 0.324"/>
    <parent link="link2"/>
    <child link="link3"/>
    <axis xyz="0 1 0"/>
    <limit effort="1000" lower="-1.0472" upper="1.32645" velocity="2.00713"/>
    <!--  limit effort, boudns? range=136 ? ? and dynamics? -->
    <dynamics damping="72" friction="50"/>
    <general6ik>0</general6ik>
  </joint>
  <joint name="joint3" type="revolute">
    <origin rpy="0 0 0" xyz="0 0 1.075"/>
    <parent link="link3"/>
    <child link="link4"/>
    <axis xyz="0 1 0"/>
    <limit effort="1000" lower="-1.83259" upper="1.8726" velocity="2.18166"/>
    <!--  limit effort, boudns? range=312 ? and dynamics? -->
    <dynamics damping="15" friction="48"/>
    <general6ik>-1.57</general6ik>
  </joint>
  <joint name="joint4" type="revolute">
    <origin rpy="0 0 0" xyz="0 0 0.225"/>
    <parent link="link4"/>
    <child link="link5"/>
    <axis xyz="1 0 0"/>
    <limit effort="940" lower="-3.14" upper="3.14" velocity="3.14159"/>
    <!--  limit effort =moment ? and dynamics? -->
    <dynamics damping="1" friction="1"/>
    <general6ik>0</general6ik>
  </joint>
  <joint name="joint5" type="revolute">
    <origin rpy="0 0 0" xyz="1.28 0 0"/>
    <parent link="link5"/>
    <child link="link6"/>
    <axis xyz="0 1 0"/>
    <limit effort="940" lower="-2.18166" upper="2.18166" velocity="3.14159"/>
    <!--  limit, bound? range=250 effort ? and dynamics? -->
    <dynamics damping="1" friction="1"/>
    <general6ik>0</general6ik>
  </joint>
  <joint name="joint6" type="revolute">
    <origin rpy="0 0 0" xyz="0.215 0 0"/>
    <parent link="link6"/>
    <child link="link7"/>
    <axis xyz="1 0 0"/>
    <limit effort="490" lower="-3.14" upper="3.14" velocity="4.53786"/>
    <!--  limit effort ? and dynamics? -->
    <dynamics damping="1" friction="1"/>
    <general6ik>0</general6ik>
  </joint>
  <link name="link1">
    <inertial>
      <mass value="550"/>
      <origin xyz="0 0 0.1"/>
      <inertia ixx="1.0" ixy="0.0" ixz="0.0" iyy="1.0" iyz="0.0" izz="1.01"/>
    </inertial>
    <collision>
      <origin rpy="0 0 0" xyz="0 0 0"/>
      <geometry>
        <mesh filename="package://yefan_description/meshes/J1.STL"/>
      </geometry>
    </collision>
    <visual>
      <origin rpy="0 0 0" xyz="0 0 0"/>
      <geometry>
        <mesh filename="package://yefan_description/meshes/J1.STL"/>
      </geometry>
    </visual>
  </link>
  <link name="link2">
    <inertial>
      <mass value="250"/>
      <origin xyz="0.2 0 0.2"/>
      <inertia ixx="1.0" ixy="0.01" ixz="0.0" iyy="1.0" iyz="0.0" izz="1.0"/>
    </inertial>
    <collision>
      <origin rpy="0 0 0" xyz="0 0 -0.346"/>
      <geometry>
        <mesh filename="package://yefan_description/meshes/J2Base.STL"/>
      </geometry>
    </collision>
    <visual>
      <origin rpy="0 0 0" xyz="0 0 -0.346"/>
      <geometry>
        <mesh filename="package://yefan_description/meshes/J2Base.STL"/>
      </geometry>
    </visual>
  </link>
  <link name="link3">
    <inertial>
      <mass value="60"/>
      <origin xyz="0 0 0.5"/>
      <inertia ixx="1.0" ixy="0.0" ixz="0.01" iyy="1.0" iyz="0.0" izz="1.0"/>
    </inertial>
    <collision>
      <origin rpy="0 0 0" xyz="-0.312 0 -0.67"/>
      <geometry>
        <mesh filename="package://yefan_description/meshes/J2Arm.STL"/>
      </geometry>
    </collision>
    <visual>
      <origin rpy="0 0 0" xyz="-0.312 0 -0.67"/>
      <geometry>
        <mesh filename="package://yefan_description/meshes/J2Arm.STL"/>
      </geometry>
    </visual>
  </link>
  <link name="link4">
    <inertial>
      <mass value="30"/>
      <origin xyz="0 0 0.1"/>
      <inertia ixx="1.0" ixy="0.0" ixz="0.0" iyy="1.0" iyz="0.01" izz="1.0"/>
    </inertial>
    <collision>
      <origin rpy="0 0 0" xyz="-0.312 0 -1.745"/>
      <geometry>
        <mesh filename="package://yefan_description/meshes/J3.STL"/>
      </geometry>
    </collision>
    <visual>
      <origin rpy="0 0 0" xyz="-0.312 0 -1.745"/>
      <geometry>
        <mesh filename="package://yefan_description/meshes/J3.STL"/>
      </geometry>
    </visual>
  </link>
  <link name="link5">
    <inertial>
      <mass value="15"/>
      <origin xyz="0.6 0 0"/>
      <inertia ixx="1.0" ixy="0.01" ixz="0.0" iyy="1.0" iyz="0.0" izz="1.0"/>
    </inertial>
    <collision>
      <origin rpy="0 0 0" xyz="-0.312 0 -1.97"/>
      <geometry>
        <mesh filename="package://yefan_description/meshes/J4.STL"/>
      </geometry>
    </collision>
    <visual>
      <origin rpy="0 0 0" xyz="-0.312 0 -1.97"/>
      <geometry>
        <mesh filename="package://yefan_description/meshes/J4.STL"/>
      </geometry>
    </visual>
  </link>
  <link name="link6">
    <inertial>
      <mass value="20"/>
      <origin xyz="0.1 0 0"/>
      <inertia ixx="1.0" ixy="0.0" ixz="0.0" iyy="1.0" iyz="0.01" izz="1.0"/>
    </inertial>
    <collision>
      <origin rpy="0 0 0" xyz="-1.592 0 -1.97"/>
      <geometry>
        <mesh filename="package://yefan_description/meshes/J5.STL"/>
      </geometry>
    </collision>
    <visual>
      <origin rpy="0 0 0" xyz="-1.592 0 -1.97"/>
      <geometry>
        <mesh filename="package://yefan_description/meshes/J5.STL"/>
      </geometry>
    </visual>
  </link>
  <link name="link7">
    <inertial>
      <mass value="2"/>
      <origin xyz="0 0.05 0"/>
      <inertia ixx="1.0" ixy="0.01" ixz="0.0" iyy="1.0" iyz="0.0" izz="1.0"/>
    </inertial>
    <collision>
      <origin rpy="0 0 0" xyz="-1.807 0 -1.97"/>
      <geometry>
        <mesh filename="package://yefan_description/meshes/J6.STL"/>
      </geometry>
    </collision>
    <visual>
      <origin rpy="0 0 0" xyz="-1.807 0 -1.97"/>
      <geometry>
        <mesh filename="package://yefan_description/meshes/J6.STL"/>
      </geometry>
    </visual>
  </link>
  <joint name="joint_balancercase" type="fixed">
    <origin rpy="0 0 0" xyz="0 0 0"/>
    <parent link="link2"/>
    <child link="link_balancercase"/>
  </joint>
  <link name="link_balancercase">
    <inertial>
      <mass value="150"/>
      <origin xyz="0.05 0 0"/>
      <inertia ixx="1.0" ixy="0.0" ixz="0.01" iyy="1.0" iyz="0.0" izz="1.0"/>
    </inertial>
    <collision>
      <origin rpy="0 0 0" xyz="0 0 -0.346"/>
      <geometry>
        <mesh filename="package://yefan_description/meshes/BalancerCase.STL"/>
      </geometry>
    </collision>
    <visual>
      <origin rpy="0 0 0" xyz="0 0 -0.346"/>
      <geometry>
        <mesh filename="package://yefan_description/meshes/BalancerCase.STL"/>
      </geometry>
    </visual>
  </link>
  <joint name="joint_balancerrod" type="fixed">
    <origin rpy="0 0 0" xyz="0 0 0"/>
    <parent link="link2"/>
    <child link="link_balancerrod"/>
  </joint>
  <link name="link_balancerrod">
    <inertial>
      <mass value="15"/>
      <origin xyz="0 0 0.05"/>
      <inertia ixx="1.0" ixy="0.0" ixz="0.01" iyy="1.0" iyz="0.0" izz="1.0"/>
    </inertial>
    <collision>
      <origin rpy="0 0 0" xyz="0 0 -0.346"/>
      <geometry>
        <mesh filename="package://yefan_description/meshes/BalancerRod.STL"/>
      </geometry>
    </collision>
    <visual>
      <origin rpy="0 0 0" xyz="0 0 -0.346"/>
      <geometry>
        <mesh filename="package://yefan_description/meshes/BalancerRod.STL"/>
      </geometry>
    </visual>
  </link>
  <joint name="joint_stopper1a" type="fixed">
    <origin rpy="0 0 0" xyz="0 0 0"/>
    <parent link="link1"/>
    <child link="link_stopper1a"/>
  </joint>
  <link name="link_stopper1a">
    <inertial>
      <mass value="2"/>
      <origin xyz="0.05 0 0"/>
      <inertia ixx="1.0" ixy="0.0" ixz="0.01" iyy="1.0" iyz="0.0" izz="1.0"/>
    </inertial>
    <collision>
      <origin rpy="0 0 0" xyz="0 0 0"/>
      <geometry>
        <mesh filename="package://yefan_description/meshes/stopper_J1_A.STL"/>
      </geometry>
    </collision>
    <visual>
      <origin rpy="0 0 0" xyz="0 0 0"/>
      <geometry>
        <mesh filename="package://yefan_description/meshes/stopper_J1_A.STL"/>
      </geometry>
    </visual>
  </link>
  <joint name="joint_stopper1b" type="fixed">
    <origin rpy="0 0 0" xyz="0 0 0"/>
    <parent link="link1"/>
    <child link="link_stopper1b"/>
  </joint>
  <link name="link_stopper1b">
    <inertial>
      <mass value="2"/>
      <origin xyz="0 0.05 0"/>
      <inertia ixx="1.0" ixy="0.0" ixz="0.0" iyy="1.0" iyz="0.01" izz="1.0"/>
    </inertial>
    <collision>
      <origin rpy="0 0 0" xyz="0 0 0"/>
      <geometry>
        <mesh filename="package://yefan_description/meshes/stopper_J1_B.STL"/>
      </geometry>
    </collision>
    <visual>
      <origin rpy="0 0 0" xyz="0 0 0"/>
      <geometry>
        <mesh filename="package://yefan_description/meshes/stopper_J1_B.STL"/>
      </geometry>
    </visual>
  </link>
  <joint name="joint_h501_j1" type="fixed">
    <origin rpy="0 0 0" xyz="0 0 0"/>
    <parent link="link1"/>
    <child link="link_h501_j1"/>
  </joint>
  <link name="link_h501_j1">
    <inertial>
      <mass value="5"/>
      <origin xyz="0 0 0.05"/>
      <inertia ixx="1.0" ixy="0.0" ixz="0.0" iyy="1.0" iyz="0.0" izz="1.0"/>
    </inertial>
    <collision>
      <origin rpy="0 0 0" xyz="0 0 0"/>
      <geometry>
        <mesh filename="package://yefan_description/meshes/H501_J1.STL"/>
      </geometry>
    </collision>
    <visual>
      <origin rpy="0 0 0" xyz="0 0 0"/>
      <geometry>
        <mesh filename="package://yefan_description/meshes/H501_J1.STL"/>
      </geometry>
    </visual>
  </link>
  <joint name="joint_h501_j3" type="fixed">
    <origin rpy="0 0 0" xyz="0 0 0"/>
    <parent link="link4"/>
    <child link="link_h501_j3"/>
  </joint>
  <link name="link_h501_j3">
    <inertial>
      <mass value="5"/>
      <origin xyz="0.05 0 0"/>
      <inertia ixx="1.0" ixy="0.0" ixz="0.01" iyy="1.0" iyz="0.0" izz="1.0"/>
    </inertial>
    <collision>
      <origin rpy="0 0 0" xyz="-0.312 0 -1.745"/>
      <geometry>
        <mesh filename="package://yefan_description/meshes/H501_J3.STL"/>
      </geometry>
    </collision>
    <visual>
      <origin rpy="0 0 0" xyz="-0.312 0 -1.745"/>
      <geometry>
        <mesh filename="package://yefan_description/meshes/H501_J3.STL"/>
      </geometry>
    </visual>
  </link>
  <joint name="joint_mcover1" type="fixed">
    <origin rpy="0 0 0" xyz="0 0 0"/>
    <parent link="link2"/>
    <child link="link_mcover1"/>
  </joint>
  <link name="link_mcover1">
    <inertial>
      <mass value="10"/>
      <origin xyz="0 0.05 0"/>
      <inertia ixx="1.0" ixy="0.0" ixz="0.01" iyy="1.0" iyz="0.0" izz="1.0"/>
    </inertial>
    <collision>
      <origin rpy="0 0 0" xyz="0 0 -0.346"/>
      <geometry>
        <mesh filename="package://yefan_description/meshes/MotorCover_J1.STL"/>
      </geometry>
    </collision>
    <visual>
      <origin rpy="0 0 0" xyz="0 0 -0.346"/>
      <geometry>
        <mesh filename="package://yefan_description/meshes/MotorCover_J1.STL"/>
      </geometry>
    </visual>
  </link>
  <joint name="joint_mcover2" type="fixed">
    <origin rpy="0 0 0" xyz="0 0 0"/>
    <parent link="link2"/>
    <child link="link_mcover2"/>
  </joint>
  <link name="link_mcover2">
    <inertial>
      <mass value="10"/>
      <origin xyz="0 0 0.05"/>
      <inertia ixx="1.0" ixy="0.0" ixz="0.0" iyy="1.0" iyz="0.0" izz="1.0"/>
    </inertial>
    <collision>
      <origin rpy="0 0 0" xyz="0 0 -0.346"/>
      <geometry>
        <mesh filename="package://yefan_description/meshes/MotorCover_J2.STL"/>
      </geometry>
    </collision>
    <visual>
      <origin rpy="0 0 0" xyz="0 0 -0.346"/>
      <geometry>
        <mesh filename="package://yefan_description/meshes/MotorCover_J2.STL"/>
      </geometry>
    </visual>
  </link>
  <!--
  <link name="link_mcover3">
    <inertial>
      <mass value="5"/>
      <origin xyz="0 0 0"/>
      <inertia ixx="0.0" ixy="0.0" ixz="0.0" iyy="0.0" iyz="0.0" izz="0.0"/>
    </inertial>
    <collision>
      <origin rpy="0 0 0" xyz="-0.312 0 -1.745"/>
      <geometry>
        <mesh filename="package://yefan_description/meshes/MotorCover_J3456_bottom.STL"/>
      </geometry>
    </collision>
    <visual>
      <origin rpy="0 0 0" xyz="-0.312 0 -1.745"/>
      <geometry>
        <mesh filename="package://yefan_description/meshes/MotorCover_J3456_bottom.STL"/>
      </geometry>
    </visual>
  </link>
  -->
  <joint name="joint_mcover3_top" type="fixed">
    <origin rpy="0 0 0" xyz="0 0 0"/>
    <parent link="link4"/>
    <child link="link_mcover3_top"/>
  </joint>
  <link name="link_mcover3_top">
    <inertial>
      <mass value="5"/>
      <origin xyz="0.05 0 0"/>
      <inertia ixx="1.0" ixy="0.0" ixz="0.01" iyy="1.0" iyz="0.0" izz="1.0"/>
    </inertial>
    <collision>
      <origin rpy="0 0 0" xyz="-0.312 0 -1.745"/>
      <geometry>
        <mesh filename="package://yefan_description/meshes/MotorCover_J3456_top.STL"/>
      </geometry>
    </collision>
    <visual>
      <origin rpy="0 0 0" xyz="-0.312 0 -1.745"/>
      <geometry>
        <mesh filename="package://yefan_description/meshes/MotorCover_J3456_top.STL"/>
      </geometry>
    </visual>
  </link>
  <joint name="joint_insflange" type="fixed">
    <origin rpy="0 0 0" xyz="0 0 0"/>
    <parent link="link7"/>
    <child link="link_insflange"/>
  </joint>
  <link name="link_insflange">
    <inertial>
      <mass value="3"/>
      <origin xyz="0 0.05 0"/>
      <inertia ixx="1.0" ixy="0.01" ixz="0.0" iyy="1.0" iyz="0.0" izz="1.0"/>
    </inertial>
    <collision>
      <origin rpy="0 0 0" xyz="-1.807 0 -1.97"/>
      <geometry>
        <mesh filename="package://yefan_description/meshes/insulated_flange.STL"/>
      </geometry>
    </collision>
    <visual>
      <origin rpy="0 0 0" xyz="-1.807 0 -1.97"/>
      <geometry>
        <mesh filename="package://yefan_description/meshes/insulated_flange.STL"/>
      </geometry>
    </visual>
  </link>
  <link name="world"/>
  <joint name="grounding" type="fixed">
    <parent link="world"/>
    <child link="link1"/>
    <origin rpy="0 0 0" xyz="0 0 0"/>
  </joint>


  
</robot>

